Workbook

Sheet INÍCIO
A1: FII Investment Tracker — Excel
A3: Ferramenta pessoal de acompanhamento e simulação educacional
A5: COMO USAR
A6: 1 | B6: Cadastre seus FIIs na aba ATIVOS. O preço atual é informado manualmente.
A7: 2 | B7: Registre aportes, compras, vendas, dividendos, taxas e demais movimentações em LANÇAMENTOS.
A8: 3 | B8: A aba CARTEIRA consolida as posições a partir dos lançamentos.
A9: 4 | B9: Use o SIMULADOR para testar cenários matemáticos com premissas definidas por você.
A10: 5 | B10: Use METAS para acompanhar patrimônio e renda passiva.
A11: 6 | B11: Consulte INDICADORES e FONTES para conteúdo educativo e referências oficiais.
A14: AVISO IMPORTANTE
A15: Esta planilha possui finalidade exclusivamente educacional e de acompanhamento pessoal. Cálculos, indicadores e simulações não constituem recomendação, indicação, consultoria ou aconselhamento financeiro. As projeções são cenários matemáticos e não representam garantia de rentabilidade. Os dados de mercado devem ser conferidos em fontes oficiais.
A20: LEGENDA DE DADOS
A21: Dado informado pelo usuário | B21: Preenchido manualmente.
A22: Dado calculado | B22: Gerado pelas fórmulas da planilha.
A23: Projeção | B23: Cenário matemático baseado nas premissas informadas.
A24: Dado de mercado | B24: Deve ser conferido em fonte oficial antes de utilização.

Sheet DASHBOARD
A1: Dashboard
A3: Patrimônio atual | C3: Total investido | E3: Resultado | G3: Rentabilidade
A4: =SUM(CARTEIRA!I5:I54) | C4: =SUM(CARTEIRA!H5:H54) | E4: =SUM(CARTEIRA!J5:J54) | G4: =IFERROR(C3/C4,0)
A6: Dividendos recebidos | C6: Aporte mensal planejado | E6: Meta patrimônio | G6: Progresso da meta
A7: =SUM(CARTEIRA!L5:L54) | C7: =METAS!B7 | E7: =METAS!B5 | G7: =METAS!B12
A10: DISTRIBUIÇÃO DA CARTEIRA
A11: Ticker | B11: Valor atual | C11: Participação
A12: =IF(CARTEIRA!A5="","",CARTEIRA!A5) | B12: =IF(A12="","",CARTEIRA!I5) | C12: =IFERROR(B12/$B$3,0)
A13: =IF(CARTEIRA!A6="","",CARTEIRA!A6) | B13: =IF(A13="","",CARTEIRA!I6) | C13: =IFERROR(B13/$B$3,0)
A14: =IF(CARTEIRA!A7="","",CARTEIRA!A7) | B14: =IF(A14="","",CARTEIRA!I7) | C14: =IFERROR(B14/$B$3,0)
A15: =IF(CARTEIRA!A8="","",CARTEIRA!A8) | B15: =IF(A15="","",CARTEIRA!I8) | C15: =IFERROR(B15/$B$3,0)
A16: =IF(CARTEIRA!A9="","",CARTEIRA!A9) | B16: =IF(A16="","",CARTEIRA!I9) | C16: =IFERROR(B16/$B$3,0)
A17: =IF(CARTEIRA!A10="","",CARTEIRA!A10) | B17: =IF(A17="","",CARTEIRA!I10) | C17: =IFERROR(B17/$B$3,0)
A18: =IF(CARTEIRA!A11="","",CARTEIRA!A11) | B18: =IF(A18="","",CARTEIRA!I11) | C18: =IFERROR(B18/$B$3,0)
A19: =IF(CARTEIRA!A12="","",CARTEIRA!A12) | B19: =IF(A19="","",CARTEIRA!I12) | C19: =IFERROR(B19/$B$3,0)
A20: =IF(CARTEIRA!A13="","",CARTEIRA!A13) | B20: =IF(A20="","",CARTEIRA!I13) | C20: =IFERROR(B20/$B$3,0)
A21: =IF(CARTEIRA!A14="","",CARTEIRA!A14) | B21: =IF(A21="","",CARTEIRA!I14) | C21: =IFERROR(B21/$B$3,0)
A22: =IF(CARTEIRA!A15="","",CARTEIRA!A15) | B22: =IF(A22="","",CARTEIRA!I15) | C22: =IFERROR(B22/$B$3,0)
A23: =IF(CARTEIRA!A16="","",CARTEIRA!A16) | B23: =IF(A23="","",CARTEIRA!I16) | C23: =IFERROR(B23/$B$3,0)
... A27: =IF(CARTEIRA!A20="","",CARTEIRA!A20) | B27: =IF(A27="","",CARTEIRA!I20) | C27: =IFERROR(B27/$B$3,0)
A28: EVOLUÇÃO DE APORTES
A29: Mês | B29: Aporte | C29: =IFERROR(B29/$B$3,0)
A30: Jan | B30: =METAS!C18 | C30: =IFERROR(B30/$B$3,0)
A31: Fev | B31: =METAS!C19 | C31: =IFERROR(B31/$B$3,0)
A32: Mar | B32: =METAS!C20 | C32: =IFERROR(B32/$B$3,0)
A33: Abr | B33: =METAS!C21 | C33: =IFERROR(B33/$B$3,0)
A34: Mai | B34: =METAS!C22 | C34: =IFERROR(B34/$B$3,0)
A35: Jun | B35: =METAS!C23 | C35: =IFERROR(B35/$B$3,0)
A36: Jul | B36: =METAS!C24 | C36: =IFERROR(B36/$B$3,0)
A37: Ago | B37: =METAS!C25 | C37: =IFERROR(B37/$B$3,0)
A38: Set | B38: =METAS!C26 | C38: =IFERROR(B38/$B$3,0)
A39: Out | B39: =METAS!C27 | C39: =IFERROR(B39/$B$3,0)
A40: Nov | B40: =METAS!C28 | C40: =IFERROR(B40/$B$3,0)
A41: Dez | B41: =METAS!C29 | C41: =IFERROR(B41/$B$3,0)
A42: =IF(CARTEIRA!A35="","",CARTEIRA!A35) | B42: =IF(A42="","",CARTEIRA!I35) | C42: =IFERROR(B42/$B$3,0)
A43: =IF(CARTEIRA!A36="","",CARTEIRA!A36) | B43: =IF(A43="","",CARTEIRA!I36) | C43: =IFERROR(B43/$B$3,0)
A44: =IF(CARTEIRA!A37="","",CARTEIRA!A37) | B44: =IF(A44="","",CARTEIRA!I37) | C44: =IFERROR(B44/$B$3,0)
A45: =IF(CARTEIRA!A38="","",CARTEIRA!A38) | B45: =IF(A45="","",CARTEIRA!I38) | C45: =IFERROR(B45/$B$3,0)
A46: =IF(CARTEIRA!A39="","",CARTEIRA!A39) | B46: =IF(A46="","",CARTEIRA!I39) | C46: =IFERROR(B46/$B$3,0)
A47: =IF(CARTEIRA!A40="","",CARTEIRA!A40) | B47: =IF(A47="","",CARTEIRA!I40) | C47: =IFERROR(B47/$B$3,0)
...

Sheet SIMULADOR
A1: Simulador de Cenários
A3: As taxas abaixo são premissas de simulação definidas pelo usuário.
A5: PREMISSAS | F5: CENÁRIOS — TAXAS INFORMADAS PELO USUÁRIO
A6: Capital inicial | B6: 0 | F6: Cenário | G6: Taxa mensal | H6: Patrimônio projetado | I6: Total aportado | J6: Rendimentos | K6: Valor real (inflação)
A7: Aporte mensal | B7: 200 | F7: Conservador | G7: 0.005 | H7: =IF($B$10="Sim",$B$6*(1+G7)^($B$8*12)+$B$7*(((1+G7)^($B$8*12)-1)/G7),$B$6+$B$7*$B$8*12) | I7: =$B$6+$B$7*$B$8*12 | J7: =H7-I7 | K7: =H7/(1+$B$9)^$B$8
A8: Prazo (anos) | B8: 5 | F8: Base | G8: 0.0108 | H8: =IF($B$10="Sim",$B$6*(1+G8)^($B$8*12)+$B$7*(((1+G8)^($B$8*12)-1)/G8),$B$6+$B$7*$B$8*12) | I8: =$B$6+$B$7*$B$8*12 | J8: =H8-I8 | K8: =H8/(1+$B$9)^$B$8
A9: Inflação anual | B9: 0.045 | F9: Otimista | G9: 0.015 | H9: =IF($B$10="Sim",$B$6*(1+G9)^($B$8*12)+$B$7*(((1+G9)^($B$8*12)-1)/G9),$B$6+$B$7*$B$8*12) | I9: =$B$6+$B$7*$B$8*12 | J9: =H9-I9 | K9: =H9/(1+$B$9)^$B$8
A10: Reinvestir rendimentos? | B10: Sim
A12: CENÁRIOS POR PRAZO — MANTENDO A TAXA BASE
A13: Prazo (anos) | B13: Taxa base | C13: Patrimônio | D13: Total aportado | E13: Rendimentos | F13: Valor real
A14: 2 | B14: =$G$8 | C14: =IF($B$10="Sim",$B$6*(1+$G$8)^(A14*12)+$B$7*(((1+$G$8)^(A14*12)-1)/$G$8),$B$6+$B$7*A14*12) | D14: =$B$6+$B$7*A14*12 | E14: =C14-D14 | F14: =C14/(1+$B$9)^A14
A15: 5 | B15: =$G$8 | C15: =IF($B$10="Sim",$B$6*(1+$G$8)^(A15*12)+$B$7*(((1+$G$8)^(A15*12)-1)/$G$8),$B$6+$B$7*A15*12) | D15: =$B$6+$B$7*A15*12 | E15: =C15-D15 | F15: =C15/(1+$B$9)^A15
A16: 10 | B16: =$G$8 | C16: =IF($B$10="Sim",$B$6*(1+$G$8)^(A16*12)+$B$7*(((1+$G$8)^(A16*12)-1)/$G$8),$B$6+$B$7*A16*12) | D16: =$B$6+$B$7*A16*12 | E16: =C16-D16 | F16: =C16/(1+$B$9)^A16
A17: 20 | B17: =$G$8 | C17: =IF($B$10="Sim",$B$6*(1+$G$8)^(A17*12)+$B$7*(((1+$G$8)^(A17*12)-1)/$G$8),$B$6+$B$7*A17*12) | D17: =$B$6+$B$7*A17*12 | E17: =C17-D17 | F17: =C17/(1+$B$9)^A17
A18: 30 | B18: =$G$8 | C18: =IF($B$10="Sim",$B$6*(1+$G$8)^(A18*12)+$B$7*(((1+$G$8)^(A18*12)-1)/$G$8),$B$6+$B$7*A18*12) | D18: =$B$6+$B$7*A18*12 | E18: =C18-D18 | F18: =C18/(1+$B$9)^A18
A21: COMPOSIÇÃO HIPOTÉTICA — EDITÁVEL
A22: Tipo | B22: Percentual | C22: Aporte mensal simulado | D22: Observação
A23: Papel | B23: 0.3 | C23: =B23*$B$7 | D23: Simulação de composição; não constitui recomendação.
A24: Tijolo | B24: 0.5 | C24: =B24*$B$7 | D24: Simulação de composição; não constitui recomendação.
A25: Híbrido | B25: 0.1 | C25: =B25*$B$7 | D25: Simulação de composição; não constitui recomendação.
A26: FOF | B26: 0.1 | C26: =B26*$B$7 | D26: Simulação de composição; não constitui recomendação.
A27: Desenvolvimento | B27: 0 | C27: =B27*$B$7 | D27: Simulação de composição; não constitui recomendação.
A28: Hotelaria | B28: 0 | C28: =B28*$B$7 | D28: Simulação de composição; não constitui recomendação.
A29: TOTAL | B29: =SUM(B23:B28) | C29: =SUM(C23:C28)

Sheet LANÇAMENTOS
A1: Lançamentos
A4: Data | B4: Tipo | C4: Ativo/Ticker | D4: Quantidade | E4: Preço | F4: Valor | G4: Observação | H4: Ano | I4: Mês
F5: =IF(OR(D5="",E5=""),"",D5*E5) | H5: =IF(A5="","",YEAR(A5)) | I5: =IF(A5="","",MONTH(A5))
F6: =IF(OR(D6="",E6=""),"",D6*E6) | H6: =IF(A6="","",YEAR(A6)) | I6: =IF(A6="","",MONTH(A6))
F7: =IF(OR(D7="",E7=""),"",D7*E7) | H7: =IF(A7="","",YEAR(A7)) | I7: =IF(A7="","",MONTH(A7))
F8: =IF(OR(D8="",E8=""),"",D8*E8) | H8: =IF(A8="","",YEAR(A8)) | I8: =IF(A8="","",MONTH(A8))
F9: =IF(OR(D9="",E9=""),"",D9*E9) | H9: =IF(A9="","",YEAR(A9)) | I9: =IF(A9="","",MONTH(A9))
F10: =IF(OR(D10="",E10=""),"",D10*E10) | H10: =IF(A10="","",YEAR(A10)) | I10: =IF(A10="","",MONTH(A10))
F11: =IF(OR(D11="",E11=""),"",D11*E11) | H11: =IF(A11="","",YEAR(A11)) | I11: =IF(A11="","",MONTH(A11))
F12: =IF(OR(D12="",E12=""),"",D12*E12) | H12: =IF(A12="","",YEAR(A12)) | I12: =IF(A12="","",MONTH(A12))
F13: =IF(OR(D13="",E13=""),"",D13*E13) | H13: =IF(A13="","",YEAR(A13)) | I13: =IF(A13="","",MONTH(A13))
F14: =IF(OR(D14="",E14=""),"",D14*E14) | H14: =IF(A14="","",YEAR(A14)) | I14: =IF(A14="","",MONTH(A14))
F15: =IF(OR(D15="",E15=""),"",D15*E15) | H15: =IF(A15="","",YEAR(A15)) | I15: =IF(A15="","",MONTH(A15))
F16: =IF(OR(D16="",E16=""),"",D16*E16) | H16: =IF(A16="","",YEAR(A16)) | I16: =IF(A16="","",MONTH(A16))
... F304: =IF(OR(D304="",E304=""),"",D304*E304) | H304: =IF(A304="","",YEAR(A304)) | I304: =IF(A304="","",MONTH(A304))

Sheet CARTEIRA
A1: Carteira
A4: Ticker | B4: Nome | C4: Tipo | D4: Segmento | E4: Quantidade | F4: Preço Médio Compra | G4: Preço Atual | H4: Valor Investido | I4: Valor Atual | J4: Resultado | K4: Rentabilidade | L4: Dividendos
B5: =IFERROR(VLOOKUP(A5,ATIVOS!$A$5:$H$54,2,FALSE),"") | C5: =IFERROR(VLOOKUP(A5,ATIVOS!$A$5:$H$54,3,FALSE),"") | D5: =IFERROR(VLOOKUP(A5,ATIVOS!$A$5:$H$54,4,FALSE),"") | E5: =IF(A5="","",SUMIFS(LANÇAMENTOS!$D$5:$D$304,LANÇAMENTOS!$C$5:$C$304,A5,LANÇAMENTOS!$B$5:$B$304,"Compra")-SUMIFS(LANÇAMENTOS!$D$5:$D$304,LANÇAMENTOS!$C$5:$C$304,A5,LANÇAMENTOS!$B$5:$B$304,"Venda")) | F5: =IFERROR(SUMIFS(LANÇAMENTOS!$F$5:$F$304,LANÇAMENTOS!$C$5:$C$304,A5,LANÇAMENTOS!$B$5:$B$304,"Compra")/SUMIFS(LANÇAMENTOS!$D$5:$D$304,LANÇAMENTOS!$C$5:$C$304,A5,LANÇAMENTOS!$B$5:$B$304,"Compra"),0) | G5: =IFERROR(VLOOKUP(A5,ATIVOS!$A$5:$H$54,7,FALSE),0) | H5: =MAX(0,E5*F5) | I5: =MAX(0,E5*G5) | J5: =I5-H5 | K5: =IFERROR(J5/H5,0) | L5: =SUMIFS(LANÇAMENTOS!$F$5:$F$304,LANÇAMENTOS!$C$5:$C$304,A5,LANÇAMENTOS!$B$5:$B$304,"Dividendos")
B6: =IFERROR(VLOOKUP(A6,ATIVOS!$A$5:$H$54,2,FALSE),"") | C6: =IFERROR(VLOOKUP(A6,ATIVOS!$A$5:$H$54,3,FALSE),"") | D6: =IFERROR(VLOOKUP(A6,ATIVOS!$A$5:$H$54,4,FALSE),"") | E6: =IF(A6="","",SUMIFS(LANÇAMENTOS!$D$5:$D$304,LANÇAMENTOS!$C$5:$C$304,A6,LANÇAMENTOS!$B$5:$B$304,"Compra")-SUMIFS(LANÇAMENTOS!$D$5:$D$304,LANÇAMENTOS!$C$5:$C$304,A6,LANÇAMENTOS!$B$5:$B$304,"Venda")) | F6: =IFERROR(SUMIFS(LANÇAMENTOS!$F$5:$F$304,LANÇAMENTOS!$C$5:$C$304,A6,LANÇAMENTOS!$B$5:$B$304,"Compra")/SUMIFS(LANÇAMENTOS!$D$5:$D$304,LANÇAMENTOS!$C$5:$C$304,A6,LANÇAMENTOS!$B$5:$B$304,"Compra"),0) | G6: =IFERROR(VLOOKUP(A6,ATIVOS!$A$5:$H$54,7,FALSE),0) | H6: =MAX(0,E6*F6) | I6: =MAX(0,E6*G6) | J6: =I6-H6 | K6: =IFERROR(J6/H6,0) | L6: =SUMIFS(LANÇAMENTOS!$F$5:$F$304,LANÇAMENTOS!$C$5:$C$304,A6,LANÇAMENTOS!$B$5:$B$304,"Dividendos")
B7: =IFERROR(VLOOKUP(A7,ATIVOS!$A$5:$H$54,2,FALSE),"") | C7: =IFERROR(VLOOKUP(A7,ATIVOS!$A$5:$H$54,3,FALSE),"") | D7: =IFERROR(VLOOKUP(A7,ATIVOS!$A$5:$H$54,4,FALSE),"") | E7: =IF(A7="","",SUMIFS(LANÇAMENTOS!$D$5:$D$304,LANÇAMENTOS!$C$5:$C$304,A7,LANÇAMENTOS!$B$5:$B$304,"Compra")-SUMIFS(LANÇAMENTOS!$D$5:$D$304,LANÇAMENTOS!$C$5:$C$304,A7,LANÇAMENTOS!$B$5:$B$304,"Venda")) | F7: =IFERROR(SUMIFS(LANÇAMENTOS!$F$5:$F$304,LANÇAMENTOS!$C$5:$C$304,A7,LANÇAMENTOS!$B$5:$B$304,"Compra")/SUMIFS(LANÇAMENTOS!$D$5:$D$304,LANÇAMENTOS!$C$5:$C$304,A7,LANÇAMENTOS!$B$5:$B$304,"Compra"),0) | G7: =IFERROR(VLOOKUP(A7,ATIVOS!$A$5:$H$54,7,FALSE),0) | H7: =MAX(0,E7*F7) | I7: =MAX(0,E7*G7) | J7: =I7-H7 | K7: =IFERROR(J7/H7,0) | L7: =SUMIFS(LANÇAMENTOS!$F$5:$F$304,LANÇAMENTOS!$C$5:$C$304,A7,LANÇAMENTOS!$B$5:$B$304,"Dividendos")
B8: =IFERROR(VLOOKUP(A8,ATIVOS!$A$5:$H$54,2,FALSE),"") | C8: =IFERROR(VLOOKUP(A8,ATIVOS!$A$5:$H$54,3,FALSE),"") | D8: =IFERROR(VLOOKUP(A8,ATIVOS!$A$5:$H$54,4,FALSE),"") | E8: =IF(A8="","",SUMIFS(LANÇAMENTOS!$D$5:$D$304,LANÇAMENTOS!$C$5:$C$304,A8,LANÇAMENTOS!$B$5:$B$304,"Compra")-SUMIFS(LANÇAMENTOS!$D$5:$D$304,LANÇAMENTOS!$C$5:$C$304,A8,LANÇAMENTOS!$B$5:$B$304,"Venda")) | F8: =IFERROR(SUMIFS(LANÇAMENTOS!$F$5:$F$304,LANÇAMENTOS!$C$5:$C$304,A8,LANÇAMENTOS!$B$5:$B$304,"Compra")/SUMIFS(LANÇAMENTOS!$D$5:$D$304,LANÇAMENTOS!$C$5:$C$304,A8,LANÇAMENTOS!$B$5:$B$304,"Compra"),0) | G8: =IFERROR(VLOOKUP(A8,ATIVOS!$A$5:$H$54,7,FALSE),0) | H8: =MAX(0,E8*F8) | I8: =MAX(0,E8*G8) | J8: =I8-H8 | K8: =IFERROR(J8/H8,0) | L8: =SUMIFS(LANÇAMENTOS!$F$5:$F$304,LANÇAMENTOS!$C$5:$C$304,A8,LANÇAMENTOS!$B$5:$B$304,"Dividendos")
B9: =IFERROR(VLOOKUP(A9,ATIVOS!$A$5:$H$54,2,FALSE),"") | C9: =IFERROR(VLOOKUP(A9,ATIVOS!$A$5:$H$54,3,FALSE),"") | D9: =IFERROR(VLOOKUP(A9,ATIVOS!$A$5:$H$54,4,FALSE),"") | E9: =IF(A9="","",SUMIFS(LANÇAMENTOS!$D$5:$D$304,LANÇAMENTOS!$C$5:$C$304,A9,LANÇAMENTOS!$B$5:$B$304,"Compra")-SUMIFS(LANÇAMENTOS!$D$5:$D$304,LANÇAMENTOS!$C$5:$C$304,A9,LANÇAMENTOS!$B$5:$B$304,"Venda")) | F9: =IFERROR(SUMIFS(LANÇAMENTOS!$F$5:$F$304,LANÇAMENTOS!$C$5:$C$304,A9,LANÇAMENTOS!$B$5:$B$304,"Compra")/SUMIFS(LANÇAMENTOS!$D$5:$D$304,LANÇAMENTOS!$C$5:$C$304,A9,LANÇAMENTOS!$B$5:$B$304,"Compra"),0) | G9: =IFERROR(VLOOKUP(A9,ATIVOS!$A$5:$H$54,7,FALSE),0) | H9: =MAX(0,E9*F9) | I9: =MAX(0,E9*G9) | J9: =I9-H9 | K9: =IFERROR(J9/H9,0) | L9: =SUMIFS(LANÇAMENTOS!$F$5:$F$304,LANÇAMENTOS!$C$5:$C$304,A9,LANÇAMENTOS!$B$5:$B$304,"Dividendos")
B10: =IFERROR(VLOOKUP(A10,ATIVOS!$A$5:$H$54,2,FALSE),"") | C10: =IFERROR(VLOOKUP(A10,ATIVOS!$A$5:$H$54,3,FALSE),"") | D10: =IFERROR(VLOOKUP(A10,ATIVOS!$A$5:$H$54,4,FALSE),"") | E10: =IF(A10="","",SUMIFS(LANÇAMENTOS!$D$5:$D$304,LANÇAMENTOS!$C$5:$C$304,A10,LANÇAMENTOS!$B$5:$B$304,"Compra")-SUMIFS(LANÇAMENTOS!$D$5:$D$304,LANÇAMENTOS!$C$5:$C$304,A10,LANÇAMENTOS!$B$5:$B$304,"Venda")) | F10: =IFERROR(SUMIFS(LANÇAMENTOS!$F$5:$F$304,LANÇAMENTOS!$C$5:$C$304,A10,LANÇAMENTOS!$B$5:$B$304,"Compra")/SUMIFS(LANÇAMENTOS!$D$5:$D$304,LANÇAMENTOS!$C$5:$C$304,A10,LANÇAMENTOS!$B$5:$B$304,"Compra"),0) | G10: =IFERROR(VLOOKUP(A10,ATIVOS!$A$5:$H$54,7,FALSE),0) | H10: =MAX(0,E10*F10) | I10: =MAX(0,E10*G10) | J10: =I10-H10 | K10: =IFERROR(J10/H10,0) | L10: =SUMIFS(LANÇAMENTOS!$F$5:$F$304,LANÇAMENTOS!$C$5:$C$304,A10,LANÇAMENTOS!$B$5:$B$304,"Dividendos")
B11: =IFERROR(VLOOKUP(A11,ATIVOS!$A$5:$H$54,2,FALSE),"") | C11: =IFERROR(VLOOKUP(A11,ATIVOS!$A$5:$H$54,3,FALSE),"") | D11: =IFERROR(VLOOKUP(A11,ATIVOS!$A$5:$H$54,4,FALSE),"") | E11: =IF(A11="","",SUMIFS(LANÇAMENTOS!$D$5:$D$304,LANÇAMENTOS!$C$5:$C$304,A11,LANÇAMENTOS!$B$5:$B$304,"Compra")-SUMIFS(LANÇAMENTOS!$D$5:$D$304,LANÇAMENTOS!$C$5:$C$304,A11,LANÇAMENTOS!$B$5:$B$304,"Venda")) | F11: =IFERROR(SUMIFS(LANÇAMENTOS!$F$5:$F$304,LANÇAMENTOS!$C$5:$C$304,A11,LANÇAMENTOS!$B$5:$B$304,"Compra")/SUMIFS(LANÇAMENTOS!$D$5:$D$304,LANÇAMENTOS!$C$5:$C$304,A11,LANÇAMENTOS!$B$5:$B$304,"Compra"),0) | G11: =IFERROR(VLOOKUP(A11,ATIVOS!$A$5:$H$54,7,FALSE),0) | H11: =MAX(0,E11*F11) | I11: =MAX(0,E11*G11) | J11: =I11-H11 | K11: =IFERROR(J11/H11,0) | L11: =SUMIFS(LANÇAMENTOS!$F$5:$F$304,LANÇAMENTOS!$C$5:$C$304,A11,LANÇAMENTOS!$B$5:$B$304,"Dividendos")
B12: =IFERROR(VLOOKUP(A12,ATIVOS!$A$5:$H$54,2,FALSE),"") | C12: =IFERROR(VLOOKUP(A12,ATIVOS!$A$5:$H$54,3,FALSE),"") | D12: =IFERROR(VLOOKUP(A12,ATIVOS!$A$5:$H$54,4,FALSE),"") | E12: =IF(A12="","",SUMIFS(LANÇAMENTOS!$D$5:$D$304,LANÇAMENTOS!$C$5:$C$304,A12,LANÇAMENTOS!$B$5:$B$304,"Compra")-SUMIFS(LANÇAMENTOS!$D$5:$D$304,LANÇAMENTOS!$C$5:$C$304,A12,LANÇAMENTOS!$B$5:$B$304,"Venda")) | F12: =IFERROR(SUMIFS(LANÇAMENTOS!$F$5:$F$304,LANÇAMENTOS!$C$5:$C$304,A12,LANÇAMENTOS!$B$5:$B$304,"Compra")/SUMIFS(LANÇAMENTOS!$D$5:$D$304,LANÇAMENTOS!$C$5:$C$304,A12,LANÇAMENTOS!$B$5:$B$304,"Compra"),0) | G12: =IFERROR(VLOOKUP(A12,ATIVOS!$A$5:$H$54,7,FALSE),0) | H12: =MAX(0,E12*F12) | I12: =MAX(0,E12*G12) | J12: =I12-H12 | K12: =IFERROR(J12/H12,0) | L12: =SUMIFS(LANÇAMENTOS!$F$5:$F$304,LANÇAMENTOS!$C$5:$C$304,A12,LANÇAMENTOS!$B$5:$B$304,"Dividendos")
B13: =IFERROR(VLOOKUP(A13,ATIVOS!$A$5:$H$54,2,FALSE),"") | C13: =IFERROR(VLOOKUP(A13,ATIVOS!$A$5:$H$54,3,FALSE),"") | D13: =IFERROR(VLOOKUP(A13,ATIVOS!$A$5:$H$54,4,FALSE),"") | E13: =IF(A13="","",SUMIFS(LANÇAMENTOS!$D$5:$D$304,LANÇAMENTOS!$C$5:$C$304,A13,LANÇAMENTOS!$B$5:$B$304,"Compra")-SUMIFS(LANÇAMENTOS!$D$5:$D$304,LANÇAMENTOS!$C$5:$C$304,A13,LANÇAMENTOS!$B$5:$B$304,"Venda")) | F13: =IFERROR(SUMIFS(LANÇAMENTOS!$F$5:$F$304,LANÇAMENTOS!$C$5:$C$304,A13,LANÇAMENTOS!$B$5:$B$304,"Compra")/SUMIFS(LANÇAMENTOS!$D$5:$D$304,LANÇAMENTOS!$C$5:$C$304,A13,LANÇAMENTOS!$B$5:$B$304,"Compra"),0) | G13: =IFERROR(VLOOKUP(A13,ATIVOS!$A$5:$H$54,7,FALSE),0) | H13: =MAX(0,E13*F13) | I13: =MAX(0,E13*G13) | J13: =I13-H13 | K13: =IFERROR(J13/H13,0) | L13: =SUMIFS(LANÇAMENTOS!$F$5:$F$304,LANÇAMENTOS!$C$5:$C$304,A13,LANÇAMENTOS!$B$5:$B$304,"Dividendos")
B14: =IFERROR(VLOOKUP(A14,ATIVOS!$A$5:$H$54,2,FALSE),"") | C14: =IFERROR(VLOOKUP(A14,ATIVOS!$A$5:$H$54,3,FALSE),"") | D14: =IFERROR(VLOOKUP(A14,ATIVOS!$A$5:$H$54,4,FALSE),"") | E14: =IF(A14="","",SUMIFS(LANÇAMENTOS!$D$5:$D$304,LANÇAMENTOS!$C$5:$C$304,A14,LANÇAMENTOS!$B$5:$B$304,"Compra")-SUMIFS(LANÇAMENTOS!$D$5:$D$304,LANÇAMENTOS!$C$5:$C$304,A14,LANÇAMENTOS!$B$5:$B$304,"Venda")) | F14: =IFERROR(SUMIFS(LANÇAMENTOS!$F$5:$F$304,LANÇAMENTOS!$C$5:$C$304,A14,LANÇAMENTOS!$B$5:$B$304,"Compra")/SUMIFS(LANÇAMENTOS!$D$5:$D$304,LANÇAMENTOS!$C$5:$C$304,A14,LANÇAMENTOS!$B$5:$B$304,"Compra"),0) | G14: =IFERROR(VLOOKUP(A14,ATIVOS!$A$5:$H$54,7,FALSE),0) | H14: =MAX(0,E14*F14) | I14: =MAX(0,E14*G14) | J14: =I14-H14 | K14: =IFERROR(J14/H14,0) | L14: =SUMIFS(LANÇAMENTOS!$F$5:$F$304,LANÇAMENTOS!$C$5:$C$304,A14,LANÇAMENTOS!$B$5:$B$304,"Dividendos")
B15: =IFERROR(VLOOKUP(A15,ATIVOS!$A$5:$H$54,2,FALSE),"") | C15: =IFERROR(VLOOKUP(A15,ATIVOS!$A$5:$H$54,3,FALSE),"") | D15: =IFERROR(VLOOKUP(A15,ATIVOS!$A$5:$H$54,4,FALSE),"") | E15: =IF(A15="","",SUMIFS(LANÇAMENTOS!$D$5:$D$304,LANÇAMENTOS!$C$5:$C$304,A15,LANÇAMENTOS!$B$5:$B$304,"Compra")-SUMIFS(LANÇAMENTOS!$D$5:$D$304,LANÇAMENTOS!$C$5:$C$304,A15,LANÇAMENTOS!$B$5:$B$304,"Venda")) | F15: =IFERROR(SUMIFS(LANÇAMENTOS!$F$5:$F$304,LANÇAMENTOS!$C$5:$C$304,A15,LANÇAMENTOS!$B$5:$B$304,"Compra")/SUMIFS(LANÇAMENTOS!$D$5:$D$304,LANÇAMENTOS!$C$5:$C$304,A15,LANÇAMENTOS!$B$5:$B$304,"Compra"),0) | G15: =IFERROR(VLOOKUP(A15,ATIVOS!$A$5:$H$54,7,FALSE),0) | H15: =MAX(0,E15*F15) | I15: =MAX(0,E15*G15) | J15: =I15-H15 | K15: =IFERROR(J15/H15,0) | L15: =SUMIFS(LANÇAMENTOS!$F$5:$F$304,LANÇAMENTOS!$C$5:$C$304,A15,LANÇAMENTOS!$B$5:$B$304,"Dividendos")
B16: =IFERROR(VLOOKUP(A16,ATIVOS!$A$5:$H$54,2,FALSE),"") | C16: =IFERROR(VLOOKUP(A16,ATIVOS!$A$5:$H$54,3,FALSE),"") | D16: =IFERROR(VLOOKUP(A16,ATIVOS!$A$5:$H$54,4,FALSE),"") | E16: =IF(A16="","",SUMIFS(LANÇAMENTOS!$D$5:$D$304,LANÇAMENTOS!$C$5:$C$304,A16,LANÇAMENTOS!$B$5:$B$304,"Compra")-SUMIFS(LANÇAMENTOS!$D$5:$D$304,LANÇAMENTOS!$C$5:$C$304,A16,LANÇAMENTOS!$B$5:$B$304,"Venda")) | F16: =IFERROR(SUMIFS(LANÇAMENTOS!$F$5:$F$304,LANÇAMENTOS!$C$5:$C$304,A16,LANÇAMENTOS!$B$5:$B$304,"Compra")/SUMIFS(LANÇAMENTOS!$D$5:$D$304,LANÇAMENTOS!$C$5:$C$304,A16,LANÇAMENTOS!$B$5:$B$304,"Compra"),0) | G16: =IFERROR(VLOOKUP(A16,ATIVOS!$A$5:$H$54,7,FALSE),0) | H16: =MAX(0,E16*F16) | I16: =MAX(0,E16*G16) | J16: =I16-H16 | K16: =IFERROR(J16/H16,0) | L16: =SUMIFS(LANÇAMENTOS!$F$5:$F$304,LANÇAMENTOS!$C$5:$C$304,A16,LANÇAMENTOS!$B$5:$B$304,"Dividendos")
... B54: =IFERROR(VLOOKUP(A54,ATIVOS!$A$5:$H$54,2,FALSE),"") | C54: =IFERROR(VLOOKUP(A54,ATIVOS!$A$5:$H$54,3,FALSE),"") | D54: =IFERROR(VLOOKUP(A54,ATIVOS!$A$5:$H$54,4,FALSE),"") | E54: =IF(A54="","",SUMIFS(LANÇAMENTOS!$D$5:$D$304,LANÇAMENTOS!$C$5:$C$304,A54,LANÇAMENTOS!$B$5:$B$304,"Compra")-SUMIFS(LANÇAMENTOS!$D$5:$D$304,LANÇAMENTOS!$C$5:$C$304,A54,LANÇAMENTOS!$B$5:$B$304,"Venda")) | F54: =IFERROR(SUMIFS(LANÇAMENTOS!$F$5:$F$304,LANÇAMENTOS!$C$5:$C$304,A54,LANÇAMENTOS!$B$5:$B$304,"Compra")/SUMIFS(LANÇAMENTOS!$D$5:$D$304,LANÇAMENTOS!$C$5:$C$304,A54,LANÇAMENTOS!$B$5:$B$304,"Compra"),0) | G54: =IFERROR(VLOOKUP(A54,ATIVOS!$A$5:$H$54,7,FALSE),0) | H54: =MAX(0,E54*F54) | I54: =MAX(0,E54*G54) | J54: =I54-H54 | K54: =IFERROR(J54/H54,0) | L54: =SUMIFS(LANÇAMENTOS!$F$5:$F$304,LANÇAMENTOS!$C$5:$C$304,A54,LANÇAMENTOS!$B$5:$B$304,"Dividendos")

Sheet METAS
A1: Metas e Planejamento
A4: METAS PRINCIPAIS
A5: Meta de patrimônio | B5: 100000
A6: Meta de renda mensal | B6: 1000
A7: Aporte mensal planejado | B7: 200
A8: Meta anual de aportes | B8: 2400
A10: Patrimônio atual | B10: =SUM(CARTEIRA!I5:I54)
A11: Dividendos recebidos | B11: =SUM(CARTEIRA!L5:L54)
A12: Progresso patrimônio | B12: =IFERROR(B10/B5,0)
A13: Valor restante | B13: =MAX(0,B5-B10)
A16: PLANEJAMENTO MENSAL
A17: Mês | B17: Meta mensal | C17: Aporte realizado | D17: % atingido | E17: Meta anual | F17: Realizado no ano
A18: Jan | B18: =$B$7 | C18: =SUMIFS(LANÇAMENTOS!$F$5:$F$304,LANÇAMENTOS!$B$5:$B$304,"Aporte",LANÇAMENTOS!$I$5:$I$304,ROW()-17) | D18: =IFERROR(C18/B18,0) | E18: =$B$8 | F18: =SUM(C$18:C18)
A19: Fev | B19: =$B$7 | C19: =SUMIFS(LANÇAMENTOS!$F$5:$F$304,LANÇAMENTOS!$B$5:$B$304,"Aporte",LANÇAMENTOS!$I$5:$I$304,ROW()-17) | D19: =IFERROR(C19/B19,0) | E19: =$B$8 | F19: =SUM(C$18:C19)
A20: Mar | B20: =$B$7 | C20: =SUMIFS(LANÇAMENTOS!$F$5:$F$304,LANÇAMENTOS!$B$5:$B$304,"Aporte",LANÇAMENTOS!$I$5:$I$304,ROW()-17) | D20: =IFERROR(C20/B20,0) | E20: =$B$8 | F20: =SUM(C$18:C20)
A21: Abr | B21: =$B$7 | C21: =SUMIFS(LANÇAMENTOS!$F$5:$F$304,LANÇAMENTOS!$B$5:$B$304,"Aporte",LANÇAMENTOS!$I$5:$I$304,ROW()-17) | D21: =IFERROR(C21/B21,0) | E21: =$B$8 | F21: =SUM(C$18:C21)
A22: Mai | B22: =$B$7 | C22: =SUMIFS(LANÇAMENTOS!$F$5:$F$304,LANÇAMENTOS!$B$5:$B$304,"Aporte",LANÇAMENTOS!$I$5:$I$304,ROW()-17) | D22: =IFERROR(C22/B22,0) | E22: =$B$8 | F22: =SUM(C$18:C22)
A23: Jun | B23: =$B$7 | C23: =SUMIFS(LANÇAMENTOS!$F$5:$F$304,LANÇAMENTOS!$B$5:$B$304,"Aporte",LANÇAMENTOS!$I$5:$I$304,ROW()-17) | D23: =IFERROR(C23/B23,0) | E23: =$B$8 | F23: =SUM(C$18:C23)
A24: Jul | B24: =$B$7 | C24: =SUMIFS(LANÇAMENTOS!$F$5:$F$304,LANÇAMENTOS!$B$5:$B$304,"Aporte",LANÇAMENTOS!$I$5:$I$304,ROW()-17) | D24: =IFERROR(C24/B24,0) | E24: =$B$8 | F24: =SUM(C$18:C24)
A25: Ago | B25: =$B$7 | C25: =SUMIFS(LANÇAMENTOS!$F$5:$F$304,LANÇAMENTOS!$B$5:$B$304,"Aporte",LANÇAMENTOS!$I$5:$I$304,ROW()-17) | D25: =IFERROR(C25/B25,0) | E25: =$B$8 | F25: =SUM(C$18:C25)
A26: Set | B26: =$B$7 | C26: =SUMIFS(LANÇAMENTOS!$F$5:$F$304,LANÇAMENTOS!$B$5:$B$304,"Aporte",LANÇAMENTOS!$I$5:$I$304,ROW()-17) | D26: =IFERROR(C26/B26,0) | E26: =$B$8 | F26: =SUM(C$18:C26)
A27: Out | B27: =$B$7 | C27: =SUMIFS(LANÇAMENTOS!$F$5:$F$304,LANÇAMENTOS!$B$5:$B$304,"Aporte",LANÇAMENTOS!$I$5:$I$304,ROW()-17) | D27: =IFERROR(C27/B27,0) | E27: =$B$8 | F27: =SUM(C$18:C27)
A28: Nov | B28: =$B$7 | C28: =SUMIFS(LANÇAMENTOS!$F$5:$F$304,LANÇAMENTOS!$B$5:$B$304,"Aporte",LANÇAMENTOS!$I$5:$I$304,ROW()-17) | D28: =IFERROR(C28/B28,0) | E28: =$B$8 | F28: =SUM(C$18:C28)
A29: Dez | B29: =$B$7 | C29: =SUMIFS(LANÇAMENTOS!$F$5:$F$304,LANÇAMENTOS!$B$5:$B$304,"Aporte",LANÇAMENTOS!$I$5:$I$304,ROW()-17) | D29: =IFERROR(C29/B29,0) | E29: =$B$8 | F29: =SUM(C$18:C29)

Sheet ATIVOS
A1: Cadastro de Ativos
A4: Ticker | B4: Nome | C4: Tipo | D4: Segmento | E4: Subsegmento | F4: Política/Estratégia | G4: Preço Atual | H4: Observação

Sheet INDICADORES
A1: Indicadores e Educação
A4: INDICADORES — LEITURA EDUCATIVA
A5: Indicador | B5: O que significa | C5: Cuidados
A6: Dividend Yield (DY) | B6: Relação entre rendimentos distribuídos e preço/valor de referência, conforme a metodologia adotada. | C6: Não existe um DY mínimo oficial que, isoladamente, determine se um FII é adequado.
A7: P/VP | B7: Compara o preço da cota com o valor patrimonial por cota. | C7: Não deve ser interpretado isoladamente como sinal automático de compra ou venda.
A8: Vacância | B8: Indicador relacionado à ocupação de imóveis, quando aplicável ao fundo. | C8: A interpretação depende do segmento, contratos, localização e estratégia do fundo.
A9: Liquidez | B9: Refere-se à facilidade de negociação de um ativo no mercado. | C9: Liquidez pode variar e não deve ser tratada como garantia de saída imediata.
A10: Rendimento | B10: Distribuições recebidas pelos cotistas, quando existentes. | C10: Distribuições futuras não são garantidas.
A14: TIPOS / CLASSIFICAÇÕES
A15: Categoria | B15: Descrição
A16: Tijolo | B16: Exposição predominantemente a imóveis físicos e operações relacionadas.
A17: Papel | B17: Exposição predominantemente a títulos/recebíveis ligados ao mercado imobiliário.
A18: Híbrido | B18: Combina diferentes tipos de ativos/estratégias.
A19: FOF | B19: Fundo que investe em cotas de outros fundos, conforme sua política.
A20: Desenvolvimento | B20: Pode envolver estratégias ligadas ao desenvolvimento imobiliário.
A21: Hotelaria | B21: Exposição relacionada ao segmento hoteleiro, quando previsto na estratégia.

Sheet FONTES
A1: Fontes Oficiais
A3: Consulte as páginas oficiais para validar conceitos, documentos e informações dos fundos.
A5: Instituição | B5: Fonte | C5: Descrição | D5: Acessar
A6: B3 | B6: Fundos de Investimento Imobiliário (FII) | C6: Informações gerais sobre negociação e FIIs. | D6: https://www.b3.com.br/pt_br/produtos-e-servicos/negociacao/renda-variavel/fundos-de-investimento-imobiliario-fii.htm
A7: B3 | B7: FIIs listados | C7: Consulta de fundos imobiliários listados na B3. | D7: https://www.b3.com.br/pt_br/produtos-e-servicos/negociacao/renda-variavel/fundos-de-investimentos/fii/fiis-listados/
A8: CVM | B8: Fundos de Investimento | C8: Informações e consultas oficiais da CVM. | D8: https://www.gov.br/cvm/pt-br/assuntos/regulados/consultas-por-participante/fundos-de-investimento
A9: CVM | B9: Fundos de Investimento Imobiliários | C9: Informações regulatórias e periódicas relacionadas aos FIIs. | D9: https://www.gov.br/cvm/pt-br/assuntos/regulados/envio-de-informacoes-a-cvm-calendario/sse/fundos-de-investimento-imobiliarios-fiis
A10: Portal do Investidor | B10: Política de investimentos e ativos | C10: Conteúdo educativo sobre política de investimento e ativos dos FIIs. | D10: https://www.gov.br/investidor/pt-br/investir/tipos-de-investimentos/fundos-de-investimentos-imobiliarios-fii/politica-de-investimentos-ativos-em-que-os-fii-investem
A11: Portal do Investidor | B11: Principais riscos | C11: Conteúdo educativo oficial sobre riscos dos FIIs. | D11: https://www.gov.br/investidor/pt-br/investir/tipos-de-investimentos/fundos-de-investimentos-imobiliarios-fii/principais-riscos

Sheet AUXILIAR
A1: Tipos de movimentação | B1: Tipos de FII | C1: Segmentos | D1: Sim/Não
A2: Aporte | B2: Papel | C2: Recebíveis | D2: Sim
A3: Compra | B3: Tijolo | C3: Logística | D3: Não
A4: Venda | B4: Híbrido | C4: Shoppings
A5: Dividendos | B5: FOF | C5: Lajes Corporativas
A6: Juros/Rendimentos | B6: Desenvolvimento | C6: Hoteleiro
A7: Taxa | B7: Hotelaria | C7: Residencial
A8: Resgate | B8: Outro | C8: Diversificado
C9: Outro
